Workbook

Sheet Results_Table16
A1: Comparison | B1: Seed | C1: Run A | D1: Run B | E1: Paired Difference D | F1: Mean(D) | G1: SD(D) | H1: Cohen dz
A2: Proposed vs. LSTM | B2: 1 | C2: 0.53741 | D2: 0.52277 | E2: =D2-C2 -> -0.01464 | F2: =AVERAGE($E$2:$E$21) -> 0.016237 | G2: =_xlfn.STDEV.S($E$2:$E$21) -> 0.01799983 | H2: =F2/G2 -> 0.90206407
A3: Proposed vs. LSTM | B3: 2 | C3: 0.56193 | D3: 0.58614 | E3: =D3-C3 -> 0.02421 | F3: =AVERAGE($E$2:$E$21) -> 0.016237 | G3: =_xlfn.STDEV.S($E$2:$E$21) -> 0.01799983 | H3: =F3/G3 -> 0.90206407
A4: Proposed vs. LSTM | B4: 3 | C4: 0.57782 | D4: 0.58025 | E4: =D4-C4 -> 0.00243 | F4: =AVERAGE($E$2:$E$21) -> 0.016237 | G4: =_xlfn.STDEV.S($E$2:$E$21) -> 0.01799983 | H4: =F4/G4 -> 0.90206407
A5: Proposed vs. LSTM | B5: 4 | C5: 0.56331 | D5: 0.60159 | E5: =D5-C5 -> 0.03828 | F5: =AVERAGE($E$2:$E$21) -> 0.016237 | G5: =_xlfn.STDEV.S($E$2:$E$21) -> 0.01799983 | H5: =F5/G5 -> 0.90206407
A6: Proposed vs. LSTM | B6: 5 | C6: 0.57882 | D6: 0.59083 | E6: =D6-C6 -> 0.01201 | F6: =AVERAGE($E$2:$E$21) -> 0.016237 | G6: =_xlfn.STDEV.S($E$2:$E$21) -> 0.01799983 | H6: =F6/G6 -> 0.90206407
A7: Proposed vs. LSTM | B7: 6 | C7: 0.5508 | D7: 0.58232 | E7: =D7-C7 -> 0.03152 | F7: =AVERAGE($E$2:$E$21) -> 0.016237 | G7: =_xlfn.STDEV.S($E$2:$E$21) -> 0.01799983 | H7: =F7/G7 -> 0.90206407
A8: Proposed vs. LSTM | B8: 7 | C8: 0.5488 | D8: 0.54448 | E8: =D8-C8 -> -0.00432 | F8: =AVERAGE($E$2:$E$21) -> 0.016237 | G8: =_xlfn.STDEV.S($E$2:$E$21) -> 0.01799983 | H8: =F8/G8 -> 0.90206407
A9: Proposed vs. LSTM | B9: 8 | C9: 0.55368 | D9: 0.57281 | E9: =D9-C9 -> 0.01913 | F9: =AVERAGE($E$2:$E$21) -> 0.016237 | G9: =_xlfn.STDEV.S($E$2:$E$21) -> 0.01799983 | H9: =F9/G9 -> 0.90206407
A10: Proposed vs. LSTM | B10: 9 | C10: 0.56593 | D10: 0.61041 | E10: =D10-C10 -> 0.04448 | F10: =AVERAGE($E$2:$E$21) -> 0.016237 | G10: =_xlfn.STDEV.S($E$2:$E$21) -> 0.01799983 | H10: =F10/G10 -> 0.90206407
A11: Proposed vs. LSTM | B11: 10 | C11: 0.57269 | D11: 0.57944 | E11: =D11-C11 -> 0.00675 | F11: =AVERAGE($E$2:$E$21) -> 0.016237 | G11: =_xlfn.STDEV.S($E$2:$E$21) -> 0.01799983 | H11: =F11/G11 -> 0.90206407
A12: Proposed vs. LSTM | B12: 11 | C12: 0.56744 | D12: 0.59483 | E12: =D12-C12 -> 0.02739 | F12: =AVERAGE($E$2:$E$21) -> 0.016237 | G12: =_xlfn.STDEV.S($E$2:$E$21) -> 0.01799983 | H12: =F12/G12 -> 0.90206407
A13: Proposed vs. LSTM | B13: 12 | C13: 0.54341 | D13: 0.53478 | E13: =D13-C13 -> -0.00863 | F13: =AVERAGE($E$2:$E$21) -> 0.016237 | G13: =_xlfn.STDEV.S($E$2:$E$21) -> 0.01799983 | H13: =F13/G13 -> 0.90206407
... A21: Proposed vs. LSTM | B21: 20 | C21: 0.55931 | D21: 0.57694 | E21: =D21-C21 -> 0.01763 | F21: =AVERAGE($E$2:$E$21) -> 0.016237 | G21: =_xlfn.STDEV.S($E$2:$E$21) -> 0.01799983 | H21: =F21/G21 -> 0.90206407
A22: Proposed vs. Transformer | B22: 1 | C22: 0.59269 | D22: 0.57475 | E22: =D22-C22 -> -0.01794 | F22: =AVERAGE($E$22:$E$41) -> 0.018942 | G22: =_xlfn.STDEV.S($E$2:$E$21) -> 0.01799983 | H22: =F22/G22 -> 1.0523433
A23: Proposed vs. Transformer | B23: 2 | C23: 0.58744 | D23: 0.61589 | E23: =D23-C23 -> 0.02845 | F23: =AVERAGE($E$22:$E$41) -> 0.018942 | G23: =_xlfn.STDEV.S($E$2:$E$21) -> 0.01799983 | H23: =F23/G23 -> 1.0523433
A24: Proposed vs. Transformer | B24: 3 | C24: 0.55741 | D24: 0.55987 | E24: =D24-C24 -> 0.00246 | F24: =AVERAGE($E$22:$E$41) -> 0.018942 | G24: =_xlfn.STDEV.S($E$2:$E$21) -> 0.01799983 | H24: =F24/G24 -> 1.0523433
A25: Proposed vs. Transformer | B25: 4 | C25: 0.57518 | D25: 0.62045 | E25: =D25-C25 -> 0.04527 | F25: =AVERAGE($E$22:$E$41) -> 0.018942 | G25: =_xlfn.STDEV.S($E$2:$E$21) -> 0.01799983 | H25: =F25/G25 -> 1.0523433
A26: Proposed vs. Transformer | B26: 5 | C26: 0.56342 | D26: 0.5773 | E26: =D26-C26 -> 0.01388 | F26: =AVERAGE($E$22:$E$41) -> 0.018942 | G26: =_xlfn.STDEV.S($E$2:$E$21) -> 0.01799983 | H26: =F26/G26 -> 1.0523433
A27: Proposed vs. Transformer | B27: 6 | C27: 0.58481 | D27: 0.62201 | E27: =D27-C27 -> 0.0372 | F27: =AVERAGE($E$22:$E$41) -> 0.018942 | G27: =_xlfn.STDEV.S($E$2:$E$21) -> 0.01799983 | H27: =F27/G27 -> 1.0523433
A28: Proposed vs. Transformer | B28: 7 | C28: 0.58819 | D28: 0.58258 | E28: =D28-C28 -> -0.00561 | F28: =AVERAGE($E$22:$E$41) -> 0.018942 | G28: =_xlfn.STDEV.S($E$2:$E$21) -> 0.01799983 | H28: =F28/G28 -> 1.0523433
A29: Proposed vs. Transformer | B29: 8 | C29: 0.59182 | D29: 0.61422 | E29: =D29-C29 -> 0.0224 | F29: =AVERAGE($E$22:$E$41) -> 0.018942 | G29: =_xlfn.STDEV.S($E$2:$E$21) -> 0.01799983 | H29: =F29/G29 -> 1.0523433
A30: Proposed vs. Transformer | B30: 9 | C30: 0.57693 | D30: 0.6296 | E30: =D30-C30 -> 0.05267 | F30: =AVERAGE($E$22:$E$41) -> 0.018942 | G30: =_xlfn.STDEV.S($E$2:$E$21) -> 0.01799983 | H30: =F30/G30 -> 1.0523433
A31: Proposed vs. Transformer | B31: 10 | C31: 0.56429 | D31: 0.5719 | E31: =D31-C31 -> 0.00761 | F31: =AVERAGE($E$22:$E$41) -> 0.018942 | G31: =_xlfn.STDEV.S($E$2:$E$21) -> 0.01799983 | H31: =F31/G31 -> 1.0523433
A32: Proposed vs. Transformer | B32: 11 | C32: 0.57931 | D32: 0.61157 | E32: =D32-C32 -> 0.03226 | F32: =AVERAGE($E$22:$E$41) -> 0.018942 | G32: =_xlfn.STDEV.S($E$2:$E$21) -> 0.01799983 | H32: =F32/G32 -> 1.0523433
A33: Proposed vs. Transformer | B33: 12 | C33: 0.55541 | D33: 0.54464 | E33: =D33-C33 -> -0.01077 | F33: =AVERAGE($E$22:$E$41) -> 0.018942 | G33: =_xlfn.STDEV.S($E$2:$E$21) -> 0.01799983 | H33: =F33/G33 -> 1.0523433
... A41: Proposed vs. Transformer | B41: 20 | C41: 0.58393 | D41: 0.60455 | E41: =D41-C41 -> 0.02062 | F41: =AVERAGE($E$22:$E$41) -> 0.018942 | G41: =_xlfn.STDEV.S($E$2:$E$21) -> 0.01799983 | H41: =F41/G41 -> 1.0523433
A42: Proposed vs. Graph WaveNet | B42: 1 | C42: 0.58429 | D42: 0.56553 | E42: =D42-C42 -> -0.01876 | F42: =AVERAGE($E$42:$E$61) -> 0.024126 | G42: =_xlfn.STDEV.S($E$2:$E$21) -> 0.01799983 | H42: =F42/G42 -> 1.340346
A43: Proposed vs. Graph WaveNet | B43: 2 | C43: 0.59331 | D43: 0.6285 | E43: =D43-C43 -> 0.03519 | F43: =AVERAGE($E$42:$E$61) -> 0.024126 | G43: =_xlfn.STDEV.S($E$2:$E$21) -> 0.01799983 | H43: =F43/G43 -> 1.340346
A44: Proposed vs. Graph WaveNet | B44: 3 | C44: 0.57541 | D44: 0.58037 | E44: =D44-C44 -> 0.00496 | F44: =AVERAGE($E$42:$E$61) -> 0.024126 | G44: =_xlfn.STDEV.S($E$2:$E$21) -> 0.01799983 | H44: =F44/G44 -> 1.340346
A45: Proposed vs. Graph WaveNet | B45: 4 | C45: 0.59993 | D45: 0.65467 | E45: =D45-C45 -> 0.05474 | F45: =AVERAGE($E$42:$E$61) -> 0.024126 | G45: =_xlfn.STDEV.S($E$2:$E$21) -> 0.01799983 | H45: =F45/G45 -> 1.340346
A46: Proposed vs. Graph WaveNet | B46: 5 | C46: 0.60982 | D46: 0.62807 | E46: =D46-C46 -> 0.01825 | F46: =AVERAGE($E$42:$E$61) -> 0.024126 | G46: =_xlfn.STDEV.S($E$2:$E$21) -> 0.01799983 | H46: =F46/G46 -> 1.340346
A47: Proposed vs. Graph WaveNet | B47: 6 | C47: 0.60131 | D47: 0.64667 | E47: =D47-C47 -> 0.04536 | F47: =AVERAGE($E$42:$E$61) -> 0.024126 | G47: =_xlfn.STDEV.S($E$2:$E$21) -> 0.01799983 | H47: =F47/G47 -> 1.340346
A48: Proposed vs. Graph WaveNet | B48: 7 | C48: 0.61682 | D48: 0.61239 | E48: =D48-C48 -> -0.00443 | F48: =AVERAGE($E$42:$E$61) -> 0.024126 | G48: =_xlfn.STDEV.S($E$2:$E$21) -> 0.01799983 | H48: =F48/G48 -> 1.340346
A49: Proposed vs. Graph WaveNet | B49: 8 | C49: 0.5828 | D49: 0.61095 | E49: =D49-C49 -> 0.02815 | F49: =AVERAGE($E$42:$E$61) -> 0.024126 | G49: =_xlfn.STDEV.S($E$2:$E$21) -> 0.01799983 | H49: =F49/G49 -> 1.340346
A50: Proposed vs. Graph WaveNet | B50: 9 | C50: 0.5868 | D50: 0.65014 | E50: =D50-C50 -> 0.06334 | F50: =AVERAGE($E$42:$E$61) -> 0.024126 | G50: =_xlfn.STDEV.S($E$2:$E$21) -> 0.01799983 | H50: =F50/G50 -> 1.340346
A51: Proposed vs. Graph WaveNet | B51: 10 | C51: 0.59168 | D51: 0.60262 | E51: =D51-C51 -> 0.01094 | F51: =AVERAGE($E$42:$E$61) -> 0.024126 | G51: =_xlfn.STDEV.S($E$2:$E$21) -> 0.01799983 | H51: =F51/G51 -> 1.340346
A52: Proposed vs. Graph WaveNet | B52: 11 | C52: 0.59793 | D52: 0.63756 | E52: =D52-C52 -> 0.03963 | F52: =AVERAGE($E$42:$E$61) -> 0.024126 | G52: =_xlfn.STDEV.S($E$2:$E$21) -> 0.01799983 | H52: =F52/G52 -> 1.340346
A53: Proposed vs. Graph WaveNet | B53: 12 | C53: 0.61069 | D53: 0.60027 | E53: =D53-C53 -> -0.01042 | F53: =AVERAGE($E$42:$E$61) -> 0.024126 | G53: =_xlfn.STDEV.S($E$2:$E$21) -> 0.01799983 | H53: =F53/G53 -> 1.340346
... A61: Proposed vs. Graph WaveNet | B61: 20 | C61: 0.59493 | D61: 0.621 | E61: =D61-C61 -> 0.02607 | F61: =AVERAGE($E$42:$E$61) -> 0.024126 | G61: =_xlfn.STDEV.S($E$2:$E$21) -> 0.01799983 | H61: =F61/G61 -> 1.340346
...

Sheet Table16_Summary
A1: Comparison | B1: Target dz (Table 16) | C1: Mean(D) | D1: SD(D) | E1: Calculated dz
A2: Proposed vs. LSTM | B2: 0.902 | C2: =AVERAGE(Results_Table16!E2:E21) -> 0.016237 | D2: =_xlfn.STDEV.S(Results_Table16!E2:E21) -> 0.01799983 | E2: =C2/D2 -> 0.90206407
A3: Proposed vs. Transformer | B3: 0.881 | C3: =AVERAGE(Results_Table16!E22:E41) -> 0.018942 | D3: =_xlfn.STDEV.S(Results_Table16!E3:E22) -> 0.018310218 | E3: =C3/D3 -> 1.0345043
A4: Proposed vs. Graph WaveNet | B4: 0.965 | C4: =AVERAGE(Results_Table16!E42:E61) -> 0.024126 | D4: =_xlfn.STDEV.S(Results_Table16!E4:E23) -> 0.018433531 | E4: =C4/D4 -> 1.3088105
A5: Proposed vs. Persistence | B5: 1.084 | C5: =AVERAGE(Results_Table16!E62:E81) -> 0.0308945 | D5: =_xlfn.STDEV.S(Results_Table16!E5:E24) -> 0.018432346 | E5: =C5/D5 -> 1.6761024
A6: Proposed vs. STGCN | B6: 0.763 | C6: =AVERAGE(Results_Table16!E82:E101) -> 0.024416 | D6: =_xlfn.STDEV.S(Results_Table16!E6:E25) -> 0.018930866 | E6: =C6/D6 -> 1.2897455
A7: 24 h adaptation vs. zero-shot | B7: 0.725 | C7: =AVERAGE(Results_Table16!E102:E121) -> 0.025738 | D7: =_xlfn.STDEV.S(Results_Table16!E7:E26) -> 0.018911429 | E7: =C7/D7 -> 1.3609759
A8: 72 h adaptation vs. zero-shot | B8: 0.784 | C8: =AVERAGE(Results_Table16!E122:E141) -> 0.0305765 | D8: =_xlfn.STDEV.S(Results_Table16!E8:E27) -> 0.019185907 | E8: =C8/D8 -> 1.5936958
A9: 7 d adaptation vs. zero-shot | B9: 0.731 | C9: =AVERAGE(Results_Table16!E142:E161) -> 0.0310685 | D9: =_xlfn.STDEV.S(Results_Table16!E9:E28) -> 0.01926341 | E9: =C9/D9 -> 1.6128245
A10: Continual vs. zero-shot | B10: 0.645 | C10: =AVERAGE(Results_Table16!E162:E181) -> 0.0296705 | D10: =_xlfn.STDEV.S(Results_Table16!E10:E29) -> 0.019296753 | E10: =C10/D10 -> 1.5375903
A11: Full vs. no harmonization | B11: 0.667 | C11: =AVERAGE(Results_Table16!E182:E201) -> 0.033018 | D11: =_xlfn.STDEV.S(Results_Table16!E11:E30) -> 0.019982818 | E11: =C11/D11 -> 1.6523195
A12: Full vs. no masking | B12: 1.03 | C12: =AVERAGE(Results_Table16!E202:E221) -> 0.05459 | D12: =_xlfn.STDEV.S(Results_Table16!E12:E31) -> 0.019959332 | E12: =C12/D12 -> 2.7350615
